Workbook

Sheet Summary
A1: AWS Cost Calculator | Document Search Service | ap-south-1 (Mumbai)
A2: Scenario: | B2: =Inputs!B5 -> Document Search Service
A3: Active Tenants: | B3: =Inputs!B6 -> 500
A4: Total Documents: | B4: =Inputs!B25 -> 100000000
A5: Peak Search QPS: | B5: =Inputs!B30 -> 1157.4074
A7: Service Category | B7: Monthly ($) | C7: Annual ($) | D7: % of Total
A8: Compute (ECS Fargate — API Pods + Index Workers) | B8: =Compute!B25 -> 158.30178 | C8: =B8*12 -> 1899.6214 | D8: =IFERROR(B8/B14,"-") -> 0.075911501
A9: Storage & Search (OpenSearch, S3, ECR) | B9: =Storage!B34 -> 456.83114 | C9: =B9*12 -> 5481.9737 | D9: =IFERROR(B9/B14,"-") -> 0.21906726
A10: Database (Aurora PostgreSQL, ElastiCache Redis) | B10: =Database!B26 -> 1166.59 | C10: =B10*12 -> 13999.08 | D10: =IFERROR(B10/B14,"-") -> 0.55942263
A11: Messaging (Amazon MQ — RabbitMQ) | B11: =Messaging!B13 -> 212.43 | C11: =B11*12 -> 2549.16 | D11: =IFERROR(B11/B14,"-") -> 0.10186796
A12: Network & Security (ALB, WAF, Route 53, Transfer) | B12: =Network!B38 -> 81.053536 | C12: =B12*12 -> 972.64244 | D12: =IFERROR(B12/B14,"-") -> 0.038868139
A13: DevOps & Observability (CodePipeline, CloudWatch) | B13: =DevOps!B24 -> 10.14 | C13: =B13*12 -> 121.68 | D13: =IFERROR(B13/B14,"-") -> 0.0048625014
A14: TOTAL | B14: =SUM(B8:B13) -> 2085.3465 | C14: =B14*12 -> 25024.158 | D14: 100.0%
A16: UNIT ECONOMICS
A17: Metric | B17: Value
A18: Cost per tenant per month ($) | B18: =IFERROR(B14/Inputs!B6,"-") -> 4.1706929
A19: Cost per tenant per year ($) | B19: =IFERROR(B14*12/Inputs!B6,"-") -> 50.048315
A20: Cost per 1M search queries ($) | B20: =IFERROR(B14/(Inputs!B26*30/1000000),"-") -> 69.511549
A21: Cost per 1M document writes ($) | B21: =IFERROR(B14/(Inputs!B27*30/1000000),"-") -> 2780.4619
A22: Cost per GB stored (raw text) ($) | B22: =IFERROR(B14/Inputs!B32,"-") -> 3.9757168
A24: Legend:
A25: Blue text + yellow background = editable input (change these to model scenarios)
A26: Green text = cross-sheet link (formula pulling from another tab)
A27: Black text = formula (calculated automatically — do not edit)
A28: Edit any blue cell in Inputs or Pricing to re-run the entire model.

Sheet Pricing
A1: AWS Pricing — ap-south-1 (Mumbai) — On-Demand
A2: Rates approximate as of May 2026. Edit any blue cell to update. Cross-check at calculator.aws before citing exact numbers.
A3: COMPUTE — ECS FARGATE
A4: Service | B4: Rate ($) | C4: Unit | D4: Notes
A5: Fargate vCPU | B5: 0.05056 | C5: per vCPU-hour | D5: ap-south-1 on-demand
A6: Fargate Memory | B6: 0.00553 | C6: per GB-hour | D6: ap-south-1 on-demand
A8: STORAGE
A9: Service | B9: Rate ($) | C9: Unit | D9: Notes
A10: S3 Standard | B10: 0.025 | C10: per GB-month | D10: hot tier
A11: S3 Infrequent Access | B11: 0.0138 | C11: per GB-month | D11: warm tier
A12: S3 Glacier Instant Retrieval | B12: 0.005 | C12: per GB-month | D12: cold tier
A13: S3 PUT requests | B13: 0.005 | C13: per 1,000 reqs
A14: S3 GET requests | B14: 0.0004 | C14: per 1,000 reqs
A15: EBS gp3 | B15: 0.0924 | C15: per GB-month | D15: OpenSearch data node volumes
A16: ECR (Container Registry) | B16: 0.1 | C16: per GB-month | D16: stored image layers
A18: DATABASE — AURORA POSTGRESQL
A19: Service | B19: Rate ($) | C19: Unit | D19: Notes
A20: Aurora db.r5.large | B20: 0.348 | C20: per hour | D20: ap-south-1
A21: Aurora db.r5.xlarge | B21: 0.696 | C21: per hour | D21: ap-south-1
A22: Aurora storage | B22: 0.11 | C22: per GB-month
A23: Aurora I/O | B23: 0.22 | C23: per 1M requests
A25: CACHE — ELASTICACHE REDIS
A26: Service | B26: Rate ($) | C26: Unit | D26: Notes
A27: ElastiCache cache.r5.large | B27: 0.273 | C27: per hour | D27: ap-south-1
A28: ElastiCache cache.r5.xlarge | B28: 0.546 | C28: per hour | D28: ap-south-1
A30: SEARCH — AMAZON OPENSEARCH SERVICE
A31: Service | B31: Rate ($) | C31: Unit | D31: Notes
A32: OpenSearch m5.large.search | B32: 0.173 | C32: per hour | D32: ap-south-1 data node
A33: OpenSearch m5.xlarge.search | B33: 0.346 | C33: per hour | D33: ap-south-1 data node
A35: MESSAGING — AMAZON MQ (RABBITMQ)
A36: Service | B36: Rate ($) | C36: Unit | D36: Notes
A37: Amazon MQ mq.m5.large | B37: 0.291 | C37: per hour | D37: single-instance broker, ap-south-1
A38: Amazon MQ mq.m5.xlarge | B38: 0.582 | C38: per hour | D38: single-instance broker, ap-south-1
A40: NETWORK & SECURITY
A41: Service | B41: Rate ($) | C41: Unit | D41: Notes
A42: Data transfer out to Internet | B42: 0.1093 | C42: per GB | D42: first 10 TB/month
A43: Inter-AZ transfer (each way) | B43: 0.02 | C43: per GB
A44: ALB base | B44: 0.0252 | C44: per hour | D44: Application Load Balancer
A45: ALB LCU | B45: 0.008 | C45: per LCU-hour
A46: Route53 hosted zone | B46: 0.5 | C46: per zone/month
...

Sheet Inputs
A1: Workload Inputs & Derived Metrics
A3: SCENARIO ASSUMPTIONS (edit blue cells)
A4: Parameter | B4: Value | C4: Unit | D4: Notes
A5: Scenario name | B5: Document Search Service | D5: preset — change to match the deployment
A6: Active tenants | B6: 500 | C6: tenants | D6: number of customer tenants on the platform
A7: Avg documents per tenant | B7: 200000 | C7: docs | D7: e.g., 10K docs avg per tenant
A8: Avg doc size — text (KB) | B8: 5 | C8: KB | D8: title + content combined
A9: Avg metadata size (KB) | B9: 0.5 | C9: KB | D9: JSON metadata field
A10: Search queries / tenant / day | B10: 2000 | C10: queries | D10: full-text search via OpenSearch
A11: Document writes / tenant / day | B11: 50 | C11: docs | D11: new docs indexed per tenant per day
A12: Media attachment rate | B12: 0.05 | C12: fraction | D12: % of docs that include a media file
A13: Avg media size (KB) | B13: 500 | C13: KB | D13: avg attachment size (image / PDF)
A14: Data retention | B14: 365 | C14: days | D14: how long documents are stored
A16: HELPER MULTIPLIERS (Rules of Thumb)
A17: Multiplier | B17: Value | C17: Unit | D17: Notes
A18: Peak-to-average multiplier | B18: 100 | C18: x | D18: 2-3x typical for B2B SaaS
A19: Cache hit ratio (search) | B19: 0.7 | C19: fraction | D19: 70% of searches served from Redis L2
A20: Replication factor | B20: 3 | C20: x | D20: 3x for CRDB + ES shard replicas
A21: Cross-AZ traffic factor | B21: 2 | C21: x | D21: inter-AZ multiplier for ingress
A23: DERIVED METRICS (formulas — do not edit)
A24: Metric | B24: Value | C24: Unit | D24: Formula reference
A25: Total documents | B25: =B6*B7 -> 100000000 | C25: docs | D25: tenants × docs per tenant
A26: Total search queries / day | B26: =B6*B10 -> 1000000 | C26: queries/day | D26: tenants × searches per tenant
A27: Total document writes / day | B27: =B6*B11 -> 25000 | C27: writes/day | D27: tenants × writes per tenant
A28: Avg searches per second | B28: =B26/86400 -> 11.574074 | C28: QPS | D28: total searches / 86,400 s
A29: Avg writes per second | B29: =B27/86400 -> 0.28935185 | C29: QPS | D29: total writes / 86,400 s
A30: Peak searches per second | B30: =B28*B18 -> 1157.4074 | C30: QPS | D30: avg × peak multiplier
A31: Peak writes per second | B31: =B29*B18 -> 28.935185 | C31: QPS | D31: avg × peak multiplier
A32: Raw text data (GB) | B32: =B6*B7*(B8+B9)/1024/1024 -> 524.52087 | C32: GB | D32: docs × (text+meta)KB ÷ 1024²
A33: Raw data with media (GB) | B33: =B32+B6*B7*B12*B13/1024/1024 -> 2908.7067 | C33: GB | D33: text + media attachments
A34: CRDB stored data — with replication (GB) | B34: =B32*B20 -> 1573.5626 | C34: GB | D34: text × replication factor
A35: ES index size — 2× raw (GB) | B35: =B32*2 -> 1049.0417 | C35: GB | D35: inverted index ~2× raw content
A36: ES with shard replicas (GB total) | B36: =B35*2 -> 2098.0835 | C36: GB | D36: primary + 1 replica per shard
A37: Monthly egress — search responses (GB) | B37: =B28*86400*30*5/1024/1024 -> 143.05115 | C37: GB/month | D37: searches/sec × 86400 × 30 × 5 KB
A38: Queue messages / month | B38: =B27*30 -> 750000 | C38: messages | D38: daily writes × 30 days
A39: Inter-AZ GB / month | B39: =B37*B21 -> 286.10229 | C39: GB/month | D39: egress × cross-AZ factor

Sheet Compute
A1: Compute Cost Breakdown
A3: ECS Fargate — API Pods (Active / Blue Environment)
A4: Parameter | B4: Value | C4: Unit | D4: Notes
A5: vCPU per task | B5: 1 | C5: vCPU | D5: handles ~500 req/s per pod
A6: Memory per task (GB) | B6: 2 | C6: GB | D6: FastAPI + asyncpg, fits comfortably
A7: Number of API tasks | B7: 3 | C7: count | D7: floor for multi-AZ; scales behind ALB
A8: Hours per month | B8: 730 | C8: hrs | D8: 24 × 365 / 12
A9: Fargate vCPU rate | B9: =Pricing!B5 -> 0.05056 | C9: $/vCPU-hr | D9: linked to Pricing!B5
A10: Fargate memory rate | B10: =Pricing!B6 -> 0.00553 | C10: $/GB-hr | D10: linked to Pricing!B6
A11: API pods monthly cost | B11: =(B5*B9+B6*B10)*B7*B8 -> 134.9478 | D11: (vCPU×rate + mem×rate) × tasks × hrs
A13: ECS Fargate — Index Workers (Active)
A14: Parameter | B14: Value | C14: Unit | D14: Notes
A15: vCPU per worker task | B15: 0.5 | C15: vCPU | D15: light async consumer — 0.5 vCPU sufficient
A16: Memory per worker task (GB) | B16: 1 | C16: GB
A17: Number of index worker tasks | B17: 1 | C17: count | D17: single worker handles low QPS; add more at 10× scale
A18: Index workers monthly cost | B18: =(B15*B9+B16*B10)*B17*B8 -> 22.4913 | D18: same hrs/month as API pods
A20: Green Environment Overhead (Blue/Green Deployment Windows)
A21: Parameter | B21: Value | C21: Unit | D21: Notes
A22: Deployment hours / month | B22: 4 | C22: hrs | D22: estimate: ~2 deploys/month × 2 hrs overlap
A23: Green env monthly overhead | B23: =(B5*B9+B6*B10)*B7*B22+(B15*B9+B16*B10)*B17*B22 -> 0.86268 | D23: spin-up green → shift ALB traffic → terminate blue
A25: TOTAL COMPUTE (Monthly) | B25: =B11+B18+B23 -> 158.30178

Sheet Storage
A1: Storage & Search Cost Breakdown
A3: Amazon OpenSearch Service (Search Index — 5 Shards, 1 Replica)
A4: Parameter | B4: Value | C4: Unit | D4: Notes
A5: Instance type | B5: m5.large.search | C5: — | D5: change rate below if upgrading to m5.xlarge
A6: Hourly rate ($/hr) | B6: =Pricing!B32 -> 0.173 | C6: $/hr | D6: Pricing!B32 — m5.large.search
A7: Number of data nodes | B7: 3 | C7: count | D7: 3 nodes spread across AZs; 3 master nodes included by AWS
A8: Hours per month | B8: 730 | C8: hrs
A9: EBS gp3 per node (GB) | B9: 20 | C9: GB | D9: holds ES shards; grow as document volume increases
A10: EBS gp3 rate | B10: =Pricing!B15 -> 0.0924 | C10: $/GB-month
A11: OpenSearch compute cost | B11: =B6*B7*B8 -> 378.87
A12: OpenSearch EBS storage cost | B12: =B9*B7*B10 -> 5.544
A13: OpenSearch subtotal | B13: =B11+B12 -> 384.414
A15: Amazon S3 (Build Artifacts + Document Media Attachments)
A16: Parameter | B16: Value | C16: Unit | D16: Notes
A17: Build artifact storage (GB) | B17: 5 | C17: GB | D17: CodeBuild output ZIPs, kept 90 days
A18: Document media storage (GB) | B18: =Inputs!B6*Inputs!B7*Inputs!B12*Inputs!B13/1024/1024 -> 2384.1858 | D18: from Inputs: tenants × docs × media_rate × media_size
A19: S3 Standard rate | B19: =Pricing!B10 -> 0.025 | C19: $/GB-month
A20: Artifact storage cost | B20: =B17*B19 -> 0.125
A21: Media storage cost | B21: =B18*B19 -> 59.604645
A22: Monthly PUT requests (media writes) | B22: =Inputs!B27*30*Inputs!B12 -> 37500 | D22: daily writes × 30 × media fraction
A23: Monthly GET requests (search-related) | B23: =Inputs!B26*30 -> 30000000 | D23: daily searches × 30
A24: S3 PUT cost | B24: =B22/1000*Pricing!B13 -> 0.1875
A25: S3 GET cost | B25: =B23/1000*Pricing!B14 -> 12
A26: S3 subtotal | B26: =B20+B21+B24+B25 -> 71.917145
A28: Amazon ECR (Container Registry)
A29: Parameter | B29: Value | C29: Unit | D29: Notes
A30: Container images stored (GB) | B30: 5 | C30: GB | D30: API image + index worker image, versioned layers
A31: ECR rate | B31: =Pricing!B16 -> 0.1 | C31: $/GB-month
A32: ECR monthly cost | B32: =B30*B31 -> 0.5
A34: TOTAL STORAGE & SEARCH (Monthly) | B34: =B13+B26+B32 -> 456.83114

Sheet Database
A1: Database Cost Breakdown
A3: Aurora PostgreSQL — Source of Truth (CockroachDB-compatible via Aurora)
A4: Parameter | B4: Value | C4: Unit | D4: Notes
A5: Instance label | B5: db.r5.large | C5: — | D5: update rate below if upgrading
A6: Hourly rate ($/hr) | B6: =Pricing!B20 -> 0.348 | C6: $/hr | D6: linked to Pricing — change rate if you resize
A7: Number of instances | B7: 2 | C7: count | D7: 1 writer + 1 read replica (multi-AZ)
A8: Hours per month | B8: 730 | C8: hrs
A9: Aurora storage (GB) | B9: =CEILING(Inputs!B34*1.5, 1) -> 2361 | D9: CRDB with replication × 1.5 headroom for WAL + indexes
A10: Aurora storage rate | B10: =Pricing!B22 -> 0.11 | C10: $/GB-month
A11: Est. Aurora I/O (millions / month) | B11: 1 | C11: M reqs | D11: increase with write volume; monitor in CloudWatch
A12: Aurora I/O rate | B12: =Pricing!B23 -> 0.22 | C12: $/1M reqs
A13: Aurora compute cost | B13: =B6*B7*B8 -> 508.08
A14: Aurora storage cost | B14: =B9*B10 -> 259.71
A15: Aurora I/O cost | B15: =B11*B12 -> 0.22
A16: Aurora subtotal | B16: =B13+B14+B15 -> 768.01
A18: ElastiCache Redis — L2 Cache + Rate Limiting (Sliding Window)
A19: Parameter | B19: Value | C19: Unit | D19: Notes
A20: Node label | B20: cache.r5.large | C20: —
A21: Hourly rate ($/hr) | B21: =Pricing!B27 -> 0.273 | C21: $/hr | D21: Pricing!B27
A22: Number of Redis nodes | B22: 2 | C22: count | D22: 1 primary + 1 read replica for HA
A23: Hours per month | B23: 730 | C23: hrs
A24: Redis monthly cost | B24: =B21*B22*B23 -> 398.58
A26: TOTAL DATABASE (Monthly) | B26: =B16+B24 -> 1166.59

Sheet Messaging
A1: Messaging Cost Breakdown
A3: Amazon MQ — RabbitMQ (Async Index Queue: CRDB Write → MQ → Worker → OpenSearch)
A4: Parameter | B4: Value | C4: Unit | D4: Notes
A5: Broker type | B5: mq.m5.large | C5: — | D5: single-instance; upgrade to active/standby for HA
A6: Hourly rate ($/hr) | B6: =Pricing!B37 -> 0.291 | C6: $/hr | D6: Pricing!B37
A7: Number of brokers | B7: 1 | C7: count | D7: scale to 2 (active/standby) for production HA
A8: Hours per month | B8: 730 | C8: hrs
A9: Broker compute cost | B9: =B6*B7*B8 -> 212.43
A11: Queue message volume / month (informational) | B11: =Inputs!B38 -> 750000 | C11: messages | D11: Included in broker cost — shown for capacity planning
A13: TOTAL MESSAGING (Monthly) | B13: =B9 -> 212.43

Sheet Network
A1: Network & Security Cost Breakdown
A3: Application Load Balancer (ALB)
A4: Parameter | B4: Value | C4: Unit | D4: Notes
A5: Number of ALBs | B5: 1 | C5: count | D5: 1 ALB routes to blue/green target groups
A6: ALB base rate | B6: =Pricing!B44 -> 0.0252 | C6: $/hr
A7: Hours per month | B7: 730 | C7: hrs
A8: Estimated LCU-hours / month | B8: 100 | C8: LCU-hrs | D8: increases with RPS; 1 LCU ~ 25 new connections/sec
A9: ALB LCU rate | B9: =Pricing!B45 -> 0.008 | C9: $/LCU-hr
A10: ALB monthly cost | B10: =B5*B6*B7+B8*B9 -> 19.196
A12: AWS WAF (DDoS + SQL Injection Protection)
A13: Parameter | B13: Value | C13: Unit | D13: Notes
A14: Number of WebACLs | B14: 1 | C14: count
A15: WAF WebACL rate | B15: =Pricing!B48 -> 5 | C15: $/WebACL/month
A16: Number of WAF rules | B16: 5 | C16: rules | D16: rate limiting, geo-block, SQL injection, XSS, known bad IPs
A17: WAF rule rate | B17: =Pricing!B49 -> 1 | C17: $/rule/month
A18: Monthly requests (millions) | B18: =Inputs!B26*30/1000000 -> 30 | C18: M reqs | D18: daily searches × 30 ÷ 1M
A19: WAF request rate | B19: =Pricing!B50 -> 0.6 | C19: $/1M reqs
A20: WAF monthly cost | B20: =B14*B15+B16*B17+B18*B19 -> 28
A22: Amazon Route 53 (DNS)
A23: Parameter | B23: Value | C23: Unit | D23: Notes
A24: Hosted zones | B24: 1 | C24: count
A25: Zone rate | B25: =Pricing!B46 -> 0.5 | C25: $/zone/month
A26: Monthly DNS queries (millions) | B26: =Inputs!B26*30/1000000 -> 30 | C26: M queries
A27: DNS query rate | B27: =Pricing!B47 -> 0.4 | C27: $/1M queries
A28: Route53 monthly cost | B28: =B24*B25+B26*B27 -> 12.5
A30: Data Transfer
A31: Parameter | B31: Value | C31: Unit | D31: Notes
A32: Monthly egress to Internet (GB) | B32: =Inputs!B37 -> 143.05115 | C32: GB | D32: linked from Inputs derived metrics
A33: Egress rate | B33: =Pricing!B42 -> 0.1093 | C33: $/GB
A34: Inter-AZ monthly (GB) | B34: =Inputs!B39 -> 286.10229 | C34: GB | D34: traffic × cross-AZ factor from Inputs
A35: Inter-AZ rate | B35: =Pricing!B43 -> 0.02 | C35: $/GB
A36: Data transfer monthly cost | B36: =B32*B33+B34*B35 -> 21.357536
A38: TOTAL NETWORK & SECURITY (Monthly) | B38: =B10+B20+B28+B36 -> 81.053536

Sheet DevOps
A1: DevOps & Observability Cost Breakdown
A3: CI/CD Pipeline (CodePipeline → CodeBuild → ECR → CodeDeploy Blue/Green)
A4: Parameter | B4: Value | C4: Unit | D4: Notes
A5: CodePipeline pipelines | B5: 1 | C5: count | D5: 1 pipeline: GitHub → Build → Deploy
A6: CodePipeline rate | B6: =Pricing!B54 -> 1 | C6: $/pipeline/month
A7: Builds per month | B7: 20 | C7: builds | D7: ~1 build/day on weekdays + PRs
A8: Avg build duration (minutes) | B8: 10 | C8: min | D8: Docker build + unit tests + push to ECR
A9: CodeBuild rate | B9: =Pricing!B55 -> 0.005 | C9: $/build-min
A10: CodePipeline monthly cost | B10: =B5*B6 -> 1
A11: CodeBuild monthly cost | B11: =B7*B8*B9 -> 1
A12: CI/CD subtotal | B12: =B10+B11 -> 2
A14: Amazon CloudWatch (Metrics + Logs + Alarms + Distributed Tracing)
A15: Parameter | B15: Value | C15: Unit | D15: Notes
A16: Custom metrics (count) | B16: 20 | C16: metrics | D16: search_latency_p95, cache_hit_ratio, queue_depth, etc.
A17: Metrics rate | B17: =Pricing!B56 -> 0.3 | C17: $/metric/month
A18: Log ingestion per month (GB) | B18: 2 | C18: GB | D18: JSON structured logs from all pods; increase at 10× scale
A19: Log ingestion rate | B19: =Pricing!B57 -> 0.57 | C19: $/GB
A20: CloudWatch alarms (count) | B20: 10 | C20: alarms | D20: p95>400ms, queue_depth>10K, ES red, CRDB node down
A21: Alarm rate | B21: =Pricing!B58 -> 0.1 | C21: $/alarm/month
A22: CloudWatch monthly cost | B22: =B16*B17+B18*B19+B20*B21 -> 8.14
A24: TOTAL DEVOPS & OBSERVABILITY (Monthly) | B24: =B12+B22 -> 10.14

Sheet Projections
A1: Cost Projections — Scale Scenarios (ap-south-1)
A2: Blue cells = editable assumptions per scenario. Costs computed from Pricing sheet rates. Fixed infra (MQ, ALB, WAF, Route53, DevOps) shown separately.
A4: Scale | B4: Tenants | C4: API Pods | D4: Index Workers | E4: Aurora Instances | F4: Redis Nodes | G4: OS Nodes | H4: Fargate Monthly ($) | I4: DB+Cache Monthly ($) | J4: Search Monthly ($) | K4: Fixed Monthly ($) | L4: TOTAL Monthly ($) | M4: Annual ($)
A5: MVP / 50 tenants | B5: 50 | C5: 3 | D5: 1 | E5: 2 | F5: 2 | G5: 3 | H5: =(C5*(1*Pricing!B5+2*Pricing!B6)+D5*(0.5*Pricing!B5+1*Pricing!B6))*730 -> 157.4391 | I5: =(E5*Pricing!B20+F5*Pricing!B27)*730 -> 906.66 | J5: =G5*(Pricing!B32*730+20*Pricing!B15) -> 384.414 | K5: =Messaging!B13+Network!B10+Network!B20+Network!B28+DevOps!B24 -> 282.266 | L5: =H5+I5+J5+K5 -> 1730.7791 | M5: =L5*12 -> 20769.349
A6: 100 tenants | B6: 100 | C6: 4 | D6: 2 | E6: 2 | F6: 2 | G6: 3 | H6: =(C6*(1*Pricing!B5+2*Pricing!B6)+D6*(0.5*Pricing!B5+1*Pricing!B6))*730 -> 224.913 | I6: =(E6*Pricing!B20+F6*Pricing!B27)*730 -> 906.66 | J6: =G6*(Pricing!B32*730+20*Pricing!B15) -> 384.414 | K6: =Messaging!B13+Network!B10+Network!B20+Network!B28+DevOps!B24 -> 282.266 | L6: =H6+I6+J6+K6 -> 1798.253 | M6: =L6*12 -> 21579.036
A7: 250 tenants | B7: 250 | C7: 6 | D7: 2 | E7: 2 | F7: 2 | G7: 3 | H7: =(C7*(1*Pricing!B5+2*Pricing!B6)+D7*(0.5*Pricing!B5+1*Pricing!B6))*730 -> 314.8782 | I7: =(E7*Pricing!B20+F7*Pricing!B27)*730 -> 906.66 | J7: =G7*(Pricing!B32*730+20*Pricing!B15) -> 384.414 | K7: =Messaging!B13+Network!B10+Network!B20+Network!B28+DevOps!B24 -> 282.266 | L7: =H7+I7+J7+K7 -> 1888.2182 | M7: =L7*12 -> 22658.618
A8: 500 tenants | B8: 500 | C8: 8 | D8: 3 | E8: 2 | F8: 4 | G8: 5 | H8: =(C8*(1*Pricing!B5+2*Pricing!B6)+D8*(0.5*Pricing!B5+1*Pricing!B6))*730 -> 427.3347 | I8: =(E8*Pricing!B20+F8*Pricing!B27)*730 -> 1305.24 | J8: =G8*(Pricing!B32*730+20*Pricing!B15) -> 640.69 | K8: =Messaging!B13+Network!B10+Network!B20+Network!B28+DevOps!B24 -> 282.266 | L8: =H8+I8+J8+K8 -> 2655.5307 | M8: =L8*12 -> 31866.368
A9: 1,000 tenants | B9: 1000 | C9: 12 | D9: 4 | E9: 3 | F9: 4 | G9: 5 | H9: =(C9*(1*Pricing!B5+2*Pricing!B6)+D9*(0.5*Pricing!B5+1*Pricing!B6))*730 -> 629.7564 | I9: =(E9*Pricing!B20+F9*Pricing!B27)*730 -> 1559.28 | J9: =G9*(Pricing!B32*730+20*Pricing!B15) -> 640.69 | K9: =Messaging!B13+Network!B10+Network!B20+Network!B28+DevOps!B24 -> 282.266 | L9: =H9+I9+J9+K9 -> 3111.9924 | M9: =L9*12 -> 37343.909
A10: 2,500 tenants | B10: 2500 | C10: 20 | D10: 6 | E10: 4 | F10: 6 | G10: 9 | H10: =(C10*(1*Pricing!B5+2*Pricing!B6)+D10*(0.5*Pricing!B5+1*Pricing!B6))*730 -> 1034.5998 | I10: =(E10*Pricing!B20+F10*Pricing!B27)*730 -> 2211.9 | J10: =G10*(Pricing!B32*730+20*Pricing!B15) -> 1153.242 | K10: =Messaging!B13+Network!B10+Network!B20+Network!B28+DevOps!B24 -> 282.266 | L10: =H10+I10+J10+K10 -> 4682.0078 | M10: =L10*12 -> 56184.094
A11: 5,000 tenants | B11: 5000 | C11: 30 | D11: 10 | E11: 6 | F11: 8 | G11: 9 | H11: =(C11*(1*Pricing!B5+2*Pricing!B6)+D11*(0.5*Pricing!B5+1*Pricing!B6))*730 -> 1574.391 | I11: =(E11*Pricing!B20+F11*Pricing!B27)*730 -> 3118.56 | J11: =G11*(Pricing!B32*730+20*Pricing!B15) -> 1153.242 | K11: =Messaging!B13+Network!B10+Network!B20+Network!B28+DevOps!B24 -> 282.266 | L11: =H11+I11+J11+K11 -> 6128.459 | M11: =L11*12 -> 73541.508
A14: Scaling Notes
A15: • Fargate: scales with tenant QPS — add pods as peak search QPS exceeds ~100 req/s per pod.
A16: • Aurora: stays on r5.large until write QPS >1K/s; vertically scale to r5.xlarge, then add read replicas.
A17: • ElastiCache: r5.large holds ~50 GB; add nodes or upgrade to r5.xlarge when cache memory exceeds 80%.
A18: • OpenSearch: 3 data nodes + 3 dedicated masters handles ~10M documents; add nodes as shard size approaches 40 GB.
A19: • Amazon MQ: single mq.m5.large handles 10K+ messages/sec; upgrade to active/standby pair for HA at 250+ tenants.
A20: • Fixed costs (ALB, WAF, Route53, DevOps, CloudWatch) ≈ constant regardless of tenant count — strong economy of scale.
A21: • Reserved Instances: ~30% savings on 1-yr (Aurora, ElastiCache) and Savings Plans on Fargate; apply after 6 months of stable load.

Sheet Cheat Sheet
A1: Architecture Reference — Numbers to Know
A3: THIS SYSTEM — COMPONENT CAPACITIES
A4: Resource / Operation | B4: Capacity / Latency | C4: Notes
A5: 1 Fargate pod (1 vCPU, 2 GB) | B5: ~500 req/s (simple JSON) | C5: FastAPI + asyncpg; 3 pods = ~1500 req/s peak
A6: 1 Aurora r5.large writer | B6: ~5,000 QPS | C6: ACID writes; add read replicas for read-heavy
A7: 1 Aurora r5.large reader | B7: ~10,000 QPS | C7: read-only; horizontal read scaling
A8: 1 ElastiCache r5.large (Redis) | B8: ~100,000 ops/sec | C8: simple GET/SET; rate limiting + L2 cache
A9: 1 OpenSearch m5.large node | B9: ~50 GB shard data | C9: grow EBS before adding nodes
A10: OpenSearch 3-node cluster | B10: ~10M documents | C10: 5 primary + 5 replica shards, 20 GB EBS/node
A11: Amazon MQ mq.m5.large | B11: ~10,000 messages/sec | C11: RabbitMQ; durable queues, delivery_mode=2
A12: ALB (Application Load Balancer) | B12: ~25,000 new conns/sec | C12: scales automatically; LCU billing
A14: LATENCY — BACK OF ENVELOPE (Jeff Dean)
A15: Resource / Operation | B15: Capacity / Latency | C15: Notes
A16: L1 cache reference | B16: 0.5 ns
A17: Main memory reference | B17: 100 ns
A18: Redis GET (same AZ) | B18: ~0.5 ms | C18: sub-ms when co-located
A19: Aurora read (primary) | B19: ~2–5 ms | C19: Raft commit adds ~2ms on CockroachDB
A20: OpenSearch full-text query | B20: ~50–150 ms | C20: properly sharded, warm cache
A21: Cross-AZ round trip | B21: ~1–2 ms | C21: ap-south-1 intra-region
A22: ES cache filter BitSet | B22: near zero | C22: tenant_id filter cached at shard level
A24: CAP THEOREM — SYSTEM POSITIONS
A25: Resource / Operation | B25: Capacity / Latency | C25: Notes
A26: CockroachDB (Aurora) | B26: CP — Serializable | C26: Under partition: refuses writes rather than lose consistency
A27: Elasticsearch (OpenSearch) | B27: AP — Eventual (~1s) | C27: Under partition: serves stale results; acceptable for search
A28: Redis (ElastiCache) | B28: AP — Eventual | C28: Cache miss handled gracefully; rate limit may be slightly loose
A29: RabbitMQ (Amazon MQ) | B29: CP for persistence | C29: Durable queues; messages survive broker restart
A31: COST LEVERS — BIGGEST SAVINGS
A32: Resource / Operation | B32: Capacity / Latency | C32: Notes
A33: Aurora Reserved Instances (1-yr) | B33: ~30% off on-demand | C33: commit after 6 months stable load
A34: Fargate Savings Plans | B34: ~20% off Fargate | C34: 1-yr commitment; no instance-type lock-in
A35: ElastiCache Reserved Nodes | B35: ~30–40% off | C35: 1- or 3-yr reserved
A36: OpenSearch Reserved Instances | B36: ~30% off | C36: 1- or 3-yr
A37: S3 Intelligent Tiering | B37: auto cost reduction | C37: media attachments auto-tier to IA after 30 days
A38: CloudFront in front of ALB | B38: ~40% egress savings | C38: caches read-heavy responses; reduces ALB LCU
A40: INTERVIEW FRAMING — SYSTEM DESIGN TIPS
A41: Resource / Operation | B41: Capacity / Latency | C41: Notes
A42: Write path | B42: CRDB → API returns 201 → MQ (async) → ES index | C42: ES is derived, rebuildable; CRDB is source of truth
A43: Read path | B43: Redis L2 cache (70% hit) → OpenSearch → Redis write | C43: 60s TTL; invalidate on write/delete
A44: Tenant isolation | B44: RLS in Aurora + tenant_id filter in every ES query | C44: defense in depth; ES filter cached at shard level
A45: Scale-out trigger | B45: CPU >70% on pods OR queue depth >10K | C45: add Fargate tasks; ALB auto-distributes
...
